Workbook

Sheet Data Source 1_customer readings
A1: Customer ID | B1: Reading Day | C1: Reading Month | D1: Reading Year | E1: Gas Reading (Price) | F1: Electric Reading (Price) | H1: Bedrooms | I1: Electricity supplier | J1: Solar Panels
A2: OXQ92940zy | B2: 17 | C2: 12 | D2: 2021 | E2: None | F2: 272.49 | H2: =_xlfn.XLOOKUP('Customer Info'!A1202,'Customer Info'!A1202:A1301,'Customer Info'!E1202:E1301,0,0) -> 0 | J2: =_xlfn.XLOOKUP('Customer Info'!A1202,'Customer Info'!A1202:A1301,'Customer Info'!M1202:M1301) -> 0
A3: OXQ92940zy | B3: 17 | C3: 1 | D3: 2021 | E3: 0 | F3: 256.37 | H3: =_xlfn.XLOOKUP('Customer Info'!A2071,'Customer Info'!A2071:A2170,'Customer Info'!E2071:E2170,0,0) -> 0 | J3: =_xlfn.XLOOKUP('Customer Info'!A2071,'Customer Info'!A2071:A2170,'Customer Info'!M2071:M2170) -> 0
A4: OFD38290ot | B4: 2 | C4: 1 | D4: 2021 | E4: 0 | F4: 246.45 | H4: =_xlfn.XLOOKUP('Customer Info'!A2072,'Customer Info'!A2072:A2171,'Customer Info'!E2072:E2171,0,0) -> 0 | J4: =_xlfn.XLOOKUP('Customer Info'!A2072,'Customer Info'!A2072:A2171,'Customer Info'!M2072:M2171) -> 0
A5: OXQ92940zy | B5: 17 | C5: 12 | D5: 2020 | E5: None | F5: 244.9 | H5: =_xlfn.XLOOKUP('Customer Info'!A2,'Customer Info'!A2:A101,'Customer Info'!E2:E101,0,0) -> 2 | I5: =_xlfn.XLOOKUP('Customer Info'!A2,'Customer Info'!A2:A101,'Customer Info'!J2:J101,0) -> Scottish Gas | J5: =_xlfn.XLOOKUP('Customer Info'!A2,'Customer Info'!A2:A101,'Customer Info'!M2:M101) -> FALSE
A6: OFD38290ot | B6: 2 | C6: 12 | D6: 2021 | E6: 0 | F6: 243.35 | H6: =_xlfn.XLOOKUP('Customer Info'!A2073,'Customer Info'!A2073:A2172,'Customer Info'!E2073:E2172,0,0) -> 0 | J6: =_xlfn.XLOOKUP('Customer Info'!A2073,'Customer Info'!A2073:A2172,'Customer Info'!M2073:M2172) -> 0
A7: OXQ92940zy | B7: 17 | C7: 11 | D7: 2021 | E7: 0 | F7: 237.9 | H7: =_xlfn.XLOOKUP('Customer Info'!A2074,'Customer Info'!A2074:A2173,'Customer Info'!E2074:E2173,0,0) -> 0 | J7: =_xlfn.XLOOKUP('Customer Info'!A2074,'Customer Info'!A2074:A2173,'Customer Info'!M2074:M2173) -> 0
A8: YOB39332fb | B8: 14 | C8: 11 | D8: 2020 | E8: 0 | F8: 234.3 | H8: =_xlfn.XLOOKUP('Customer Info'!A877,'Customer Info'!A877:A976,'Customer Info'!E877:E976,0,0) -> 0 | J8: =_xlfn.XLOOKUP('Customer Info'!A877,'Customer Info'!A877:A976,'Customer Info'!M877:M976) -> 0
A9: YOB39332fb | B9: 14 | C9: 1 | D9: 2021 | E9: 0 | F9: 233.74 | H9: =_xlfn.XLOOKUP('Customer Info'!A2075,'Customer Info'!A2075:A2174,'Customer Info'!E2075:E2174,0,0) -> 0 | J9: =_xlfn.XLOOKUP('Customer Info'!A2075,'Customer Info'!A2075:A2174,'Customer Info'!M2075:M2174) -> 0
A10: SDI07287zg | B10: 22 | C10: 11 | D10: 2021 | E10: 0 | F10: 231.9 | H10: =_xlfn.XLOOKUP('Customer Info'!A2076,'Customer Info'!A2076:A2175,'Customer Info'!E2076:E2175,0,0) -> 0 | J10: =_xlfn.XLOOKUP('Customer Info'!A2076,'Customer Info'!A2076:A2175,'Customer Info'!M2076:M2175) -> 0
A11: OFD38290ot | B11: 2 | C11: 11 | D11: 2021 | E11: None | F11: 226.8 | H11: =_xlfn.XLOOKUP('Customer Info'!A1203,'Customer Info'!A1203:A1302,'Customer Info'!E1203:E1302,0,0) -> 0 | J11: =_xlfn.XLOOKUP('Customer Info'!A1203,'Customer Info'!A1203:A1302,'Customer Info'!M1203:M1302) -> 0
A12: BAK65354tq | B12: 5 | C12: 11 | D12: 2021 | E12: 0 | F12: 224.1 | H12: =_xlfn.XLOOKUP('Customer Info'!A2077,'Customer Info'!A2077:A2176,'Customer Info'!E2077:E2176,0,0) -> 0 | J12: =_xlfn.XLOOKUP('Customer Info'!A2077,'Customer Info'!A2077:A2176,'Customer Info'!M2077:M2176) -> 0
A13: OXQ92940zy | B13: 17 | C13: 2 | D13: 2020 | E13: 0 | F13: 223.72 | H13: =_xlfn.XLOOKUP('Customer Info'!A878,'Customer Info'!A878:A977,'Customer Info'!E878:E977,0,0) -> 0 | J13: =_xlfn.XLOOKUP('Customer Info'!A878,'Customer Info'!A878:A977,'Customer Info'!M878:M977) -> 0
A14: BAK65354tq | B14: 5 | C14: 12 | D14: 2021 | E14: None | F14: 222.89 | H14: =_xlfn.XLOOKUP('Customer Info'!A1204,'Customer Info'!A1204:A1303,'Customer Info'!E1204:E1303,0,0) -> 0 | J14: =_xlfn.XLOOKUP('Customer Info'!A1204,'Customer Info'!A1204:A1303,'Customer Info'!M1204:M1303) -> 0
A15: QJY78975xx | B15: 1 | C15: 1 | D15: 2021 | E15: 0 | F15: 222.89 | H15: =_xlfn.XLOOKUP('Customer Info'!A2078,'Customer Info'!A2078:A2177,'Customer Info'!E2078:E2177,0,0) -> 0 | J15: =_xlfn.XLOOKUP('Customer Info'!A2078,'Customer Info'!A2078:A2177,'Customer Info'!M2078:M2177) -> 0
A16: YFB97062xj | B16: 5 | C16: 12 | D16: 2021 | E16: 0 | F16: 221.03 | H16: =_xlfn.XLOOKUP('Customer Info'!A2079,'Customer Info'!A2079:A2178,'Customer Info'!E2079:E2178,0,0) -> 0 | J16: =_xlfn.XLOOKUP('Customer Info'!A2079,'Customer Info'!A2079:A2178,'Customer Info'!M2079:M2178) -> 0
A17: OXQ92940zy | B17: 17 | C17: 1 | D17: 2020 | E17: 0 | F17: 220.72 | H17: =_xlfn.XLOOKUP('Customer Info'!A879,'Customer Info'!A879:A978,'Customer Info'!E879:E978,0,0) -> 0 | J17: =_xlfn.XLOOKUP('Customer Info'!A879,'Customer Info'!A879:A978,'Customer Info'!M879:M978) -> 0
A18: CKQ72473xh | B18: 8 | C18: 1 | D18: 2020 | E18: 0 | F18: 219.48 | H18: =_xlfn.XLOOKUP('Customer Info'!A880,'Customer Info'!A880:A979,'Customer Info'!E880:E979,0,0) -> 0 | J18: =_xlfn.XLOOKUP('Customer Info'!A880,'Customer Info'!A880:A979,'Customer Info'!M880:M979) -> 0
A19: BAK65354tq | B19: 5 | C19: 1 | D19: 2021 | E19: 0 | F19: 219.17 | H19: =_xlfn.XLOOKUP('Customer Info'!A2080,'Customer Info'!A2080:A2179,'Customer Info'!E2080:E2179,0,0) -> 0 | J19: =_xlfn.XLOOKUP('Customer Info'!A2080,'Customer Info'!A2080:A2179,'Customer Info'!M2080:M2179) -> 0
A20: PBR62140zd | B20: 14 | C20: 1 | D20: 2021 | E20: 0 | F20: 218.86 | H20: =_xlfn.XLOOKUP('Customer Info'!A2081,'Customer Info'!A2081:A2180,'Customer Info'!E2081:E2180,0,0) -> 0 | J20: =_xlfn.XLOOKUP('Customer Info'!A2081,'Customer Info'!A2081:A2180,'Customer Info'!M2081:M2180) -> 0
A21: SDI07287zg | B21: 22 | C21: 11 | D21: 2020 | E21: 0 | F21: 217.5 | H21: =_xlfn.XLOOKUP('Customer Info'!A881,'Customer Info'!A881:A980,'Customer Info'!E881:E980,0,0) -> 0 | J21: =_xlfn.XLOOKUP('Customer Info'!A881,'Customer Info'!A881:A980,'Customer Info'!M881:M980) -> 0
A22: PCY81777xu | B22: 15 | C22: 11 | D22: 2021 | E22: 0 | F22: 216.9 | H22: =_xlfn.XLOOKUP('Customer Info'!A2082,'Customer Info'!A2082:A2181,'Customer Info'!E2082:E2181,0,0) -> 0 | J22: =_xlfn.XLOOKUP('Customer Info'!A2082,'Customer Info'!A2082:A2181,'Customer Info'!M2082:M2181) -> 0
A23: OXQ92940zy | B23: 17 | C23: 2 | D23: 2021 | E23: 0 | F23: 214.48 | H23: =_xlfn.XLOOKUP('Customer Info'!A2083,'Customer Info'!A2083:A2182,'Customer Info'!E2083:E2182,0,0) -> 0 | J23: =_xlfn.XLOOKUP('Customer Info'!A2083,'Customer Info'!A2083:A2182,'Customer Info'!M2083:M2182) -> 0
A24: OXQ92940zy | B24: 17 | C24: 11 | D24: 2020 | E24: 0 | F24: 213.9 | H24: =_xlfn.XLOOKUP('Customer Info'!A882,'Customer Info'!A882:A981,'Customer Info'!E882:E981,0,0) -> 0 | J24: =_xlfn.XLOOKUP('Customer Info'!A882,'Customer Info'!A882:A981,'Customer Info'!M882:M981) -> 0
A25: VJT76037py | B25: 5 | C25: 11 | D25: 2021 | E25: 0 | F25: 213.9 | H25: =_xlfn.XLOOKUP('Customer Info'!A2084,'Customer Info'!A2084:A2183,'Customer Info'!E2084:E2183,0,0) -> 0 | J25: =_xlfn.XLOOKUP('Customer Info'!A2084,'Customer Info'!A2084:A2183,'Customer Info'!M2084:M2183) -> 0
A26: QJY78975xx | B26: 1 | C26: 12 | D26: 2021 | E26: None | F26: 211.73 | H26: =_xlfn.XLOOKUP('Customer Info'!A1205,'Customer Info'!A1205:A1304,'Customer Info'!E1205:E1304,0,0) -> 0 | J26: =_xlfn.XLOOKUP('Customer Info'!A1205,'Customer Info'!A1205:A1304,'Customer Info'!M1205:M1304) -> 0
A27: RQP11655zi | B27: 22 | C27: 12 | D27: 2020 | E27: 0 | F27: 209.87 | H27: =_xlfn.XLOOKUP('Customer Info'!A883,'Customer Info'!A883:A982,'Customer Info'!E883:E982,0,0) -> 0 | J27: =_xlfn.XLOOKUP('Customer Info'!A883,'Customer Info'!A883:A982,'Customer Info'!M883:M982) -> 0
A28: OFD38290ot | B28: 2 | C28: 1 | D28: 2020 | E28: 0 | F28: 209.25 | H28: =_xlfn.XLOOKUP('Customer Info'!A884,'Customer Info'!A884:A983,'Customer Info'!E884:E983,0,0) -> 0 | J28: =_xlfn.XLOOKUP('Customer Info'!A884,'Customer Info'!A884:A983,'Customer Info'!M884:M983) -> 0
A29: RQP11655zi | B29: 22 | C29: 1 | D29: 2020 | E29: 0 | F29: 209.25 | H29: =_xlfn.XLOOKUP('Customer Info'!A885,'Customer Info'!A885:A984,'Customer Info'!E885:E984,0,0) -> 0 | J29: =_xlfn.XLOOKUP('Customer Info'!A885,'Customer Info'!A885:A984,'Customer Info'!M885:M984) -> 0
A30: JGD49544db | B30: 2 | C30: 1 | D30: 2021 | E30: 0 | F30: 208.01 | H30: =_xlfn.XLOOKUP('Customer Info'!A2085,'Customer Info'!A2085:A2184,'Customer Info'!E2085:E2184,0,0) -> 0 | J30: =_xlfn.XLOOKUP('Customer Info'!A2085,'Customer Info'!A2085:A2184,'Customer Info'!M2085:M2184) -> 0
A31: BQY08319vl | B31: 12 | C31: 12 | D31: 2021 | E31: 0 | F31: 206.77 | H31: =_xlfn.XLOOKUP('Customer Info'!A2086,'Customer Info'!A2086:A2185,'Customer Info'!E2086:E2185,0,0) -> 0 | J31: =_xlfn.XLOOKUP('Customer Info'!A2086,'Customer Info'!A2086:A2185,'Customer Info'!M2086:M2185) -> 0
A32: LQK10370cq | B32: 20 | C32: 12 | D32: 2020 | E32: None | F32: 206.46 | H32: =_xlfn.XLOOKUP('Customer Info'!A3,'Customer Info'!A3:A102,'Customer Info'!E3:E102,0,0) -> 3 | I32: =_xlfn.XLOOKUP('Customer Info'!A3,'Customer Info'!A3:A102,'Customer Info'!J3:J102,0) -> Scottish Gas | J32: =_xlfn.XLOOKUP('Customer Info'!A3,'Customer Info'!A3:A102,'Customer Info'!M3:M102) -> FALSE
A33: LQK10370cq | B33: 20 | C33: 11 | D33: 2020 | E33: 0 | F33: 206.4 | H33: =_xlfn.XLOOKUP('Customer Info'!A886,'Customer Info'!A886:A985,'Customer Info'!E886:E985,0,0) -> 0 | J33: =_xlfn.XLOOKUP('Customer Info'!A886,'Customer Info'!A886:A985,'Customer Info'!M886:M985) -> 0
A34: BAK65354tq | B34: 5 | C34: 11 | D34: 2020 | E34: None | F34: 206.1 | H34: =_xlfn.XLOOKUP('Customer Info'!A4,'Customer Info'!A4:A103,'Customer Info'!E4:E103,0,0) -> 2 | I34: =_xlfn.XLOOKUP('Customer Info'!A4,'Customer Info'!A4:A103,'Customer Info'!J4:J103,0) -> SSW | J34: =_xlfn.XLOOKUP('Customer Info'!A4,'Customer Info'!A4:A103,'Customer Info'!M4:M103) -> FALSE
A35: QJY78975xx | B35: 1 | C35: 11 | D35: 2021 | E35: 0 | F35: 206.1 | H35: =_xlfn.XLOOKUP('Customer Info'!A2087,'Customer Info'!A2087:A2186,'Customer Info'!E2087:E2186,0,0) -> 0 | J35: =_xlfn.XLOOKUP('Customer Info'!A2087,'Customer Info'!A2087:A2186,'Customer Info'!M2087:M2186) -> 0
A36: BAK65354tq | B36: 5 | C36: 1 | D36: 2020 | E36: 0 | F36: 205.84 | H36: =_xlfn.XLOOKUP('Customer Info'!A887,'Customer Info'!A887:A986,'Customer Info'!E887:E986,0,0) -> 0 | J36: =_xlfn.XLOOKUP('Customer Info'!A887,'Customer Info'!A887:A986,'Customer Info'!M887:M986) -> 0
A37: GOC42881px | B37: 5 | C37: 12 | D37: 2021 | E37: 0 | F37: 205.53 | H37: =_xlfn.XLOOKUP('Customer Info'!A2088,'Customer Info'!A2088:A2187,'Customer Info'!E2088:E2187,0,0) -> 0 | J37: =_xlfn.XLOOKUP('Customer Info'!A2088,'Customer Info'!A2088:A2187,'Customer Info'!M2088:M2187) -> 0
A38: OFD38290ot | B38: 2 | C38: 11 | D38: 2020 | E38: 0 | F38: 205.5 | H38: =_xlfn.XLOOKUP('Customer Info'!A888,'Customer Info'!A888:A987,'Customer Info'!E888:E987,0,0) -> 0 | J38: =_xlfn.XLOOKUP('Customer Info'!A888,'Customer Info'!A888:A987,'Customer Info'!M888:M987) -> 0
A39: YFB97062xj | B39: 5 | C39: 1 | D39: 2020 | E39: 0 | F39: 205.22 | H39: =_xlfn.XLOOKUP('Customer Info'!A889,'Customer Info'!A889:A988,'Customer Info'!E889:E988,0,0) -> 0 | J39: =_xlfn.XLOOKUP('Customer Info'!A889,'Customer Info'!A889:A988,'Customer Info'!M889:M988) -> 0
A40: RQP11655zi | B40: 22 | C40: 1 | D40: 2021 | E40: 0 | F40: 205.22 | H40: =_xlfn.XLOOKUP('Customer Info'!A2089,'Customer Info'!A2089:A2188,'Customer Info'!E2089:E2188,0,0) -> 0 | J40: =_xlfn.XLOOKUP('Customer Info'!A2089,'Customer Info'!A2089:A2188,'Customer Info'!M2089:M2188) -> 0
...

Sheet Customer Info
A1: Customer ID | B1: Account Holder | C1: Customer Address | D1: House Type | E1: Bedrooms | F1: Boiler Fuel Type | G1: Tariff Type | H1: Renewable Sources | I1: Gas Supplier | J1: Electricity Supplier | K1: EPC Rating | L1: Insulated | M1: Solar Panels
A2: GOC42881px | B2: Tove Okyere-Field | C2: 10 Greenwood Green, East Leahland, East Lothian, W19 8SB | D2: Semi Detached | E2: 2 | F2: Electric | G2: Fixed | H2: FALSE | J2: Scottish Gas | K2: F | L2: TRUE | M2: FALSE
A3: WBO33198ot | B3: Anouk Venkataraman | C3: 75 Frost Avenue, New Garry, Clackmannanshire, W8K 7UE | D3: Detached | E3: 3 | F3: Electric | G3: Fixed | H3: FALSE | J3: Scottish Gas | K3: B | L3: TRUE | M3: FALSE
A4: XDF12820ir | B4: Maria Hamel | C4: 20 Oliver Road, West Lesley, Fife, G19 5UG | D4: Mid Terrace | E4: 2 | F4: Electric | G4: Fixed | H4: FALSE | J4: SSW | K4: F | L4: TRUE | M4: FALSE
A5: UPF42692ng | B5: Einar Afrakomaa | C5: 47 Johnson Avenue, North Linda, Moray, E31 8TA | D5: End of Terrace | E5: 4 | F5: Gas | G5: Fixed | H5: TRUE | I5: Scottish Gas | J5: Scottish Gas | K5: B | L5: FALSE | M5: FALSE
A6: ZGO86289zp | B6: Gorm Tuohey-Martel | C6: 20 Humphries Green, West Jeremymouth, Greater London, SK55 1AF | D6: Semi Detached | E6: 2 | F6: Gas | G6: Fixed | H6: TRUE | I6: Scottish Gas | J6: Scottish Gas | K6: B | L6: TRUE | M6: FALSE
A7: LCF17413kn | B7: Danielle Harris | C7: 9 Henderson Court, South Paigeview, Somerset, SS9 1NF | D7: Semi Detached | E7: 4 | F7: Gas | G7: Fixed | H7: FALSE | I7: Mpower | J7: Scottish Gas | K7: C | L7: TRUE | M7: FALSE
A8: RXY68626yj | B8: Ishita Deshpande | C8: 9 Morton Court, Graemestad, Wiltshire, N66 0HZ | D8: End of Terrace | E8: 4 | F8: Gas | G8: Variable | H8: FALSE | I8: SSW | J8: SSW | K8: D | L8: TRUE | M8: FALSE
A9: UBA60393vv | B9: Sheree Brown | C9: 5 Gibbons Green, North Kellytown, Northamptonshire, BH1 0NR | D9: Semi Detached | E9: 2 | F9: Gas | G9: Fixed | H9: FALSE | I9: Mpower | J9: Mpower | K9: D | L9: TRUE | M9: FALSE
A10: AWE86553lb | B10: Lawrence Sem-Leroux | C10: 72 Holmes Street, New Alicemouth, Buckinghamshire, B81 9JJ | D10: Mid Terrace | E10: 3 | F10: Gas | G10: Fixed | H10: FALSE | I10: SSW | J10: SSW | K10: E | L10: TRUE | M10: FALSE
A11: OVP60227cf | B11: Fiifi Phillips | C11: 69 Young Green, Ashleyborough, North Ayrshire, AB8 7AU | D11: Semi Detached | E11: 2 | F11: Gas | G11: Fixed | H11: TRUE | I11: DEF Energy | J11: Scottish Gas | K11: E | L11: TRUE | M11: FALSE
A12: ABS01137oq | B12: Bradley Cole | C12: 2 Singh Avenue, North Lydiachester, Greater Manchester, E25 9AN | D12: Mid Terrace | E12: 2 | F12: Electric | G12: Variable | H12: FALSE | J12: SSW | K12: A | L12: TRUE | M12: FALSE
A13: RXY39708bo | B13: Mads Shankar | C13: 5 Adams Avenue, Porterville, Hampshire, N1A 6YL | D13: Bungalow | E13: 2 | F13: Gas | G13: Fixed | H13: TRUE | I13: Scottish Gas | J13: Scottish Gas | K13: D | L13: TRUE | M13: FALSE
A14: JCG46776vt | B14: Denise Tailor | C14: 18 Turner Green, West Samuelfurt, Shropshire, L00 2AN | D14: Mid Terrace | E14: 3 | F14: Electric | G14: Fixed | H14: FALSE | J14: Scottish Gas | K14: D | L14: TRUE | M14: TRUE
A15: KSA79823ta | B15: Emer Agyemang | C15: 29 Carpenter Avenue, East Samantha, Orkney Islands, G2T 9YD | D15: Detached | E15: 3 | F15: Gas | G15: Variable | H15: TRUE | I15: Scottish Gas | J15: Scottish Gas | K15: A | L15: TRUE | M15: FALSE
A16: UOT01483nx | B16: Margot Hamon | C16: 26 Harris Green, Charlenestad, Scottish Borders, L8 2SH | D16: End of Terrace | E16: 4 | F16: Gas | G16: Fixed | H16: FALSE | I16: Scottish Gas | J16: Scottish Gas | K16: B | L16: FALSE | M16: FALSE
A17: OXQ92940zy | B17: Padraic Dada | C17: 32 Collins Road, South Reece, Durham, M6J 1XN | D17: End of Terrace | E17: 4 | F17: Electric | G17: Variable | H17: FALSE | J17: Scottish Gas | K17: A | L17: FALSE | M17: FALSE
A18: UAM51525zs | B18: Tonny MacGill | C18: 21 Gregory Road, Wellstown, Inverclyde, RM4 8YX | D18: Mid Terrace | E18: 4 | F18: Gas | G18: Fixed | H18: FALSE | I18: DEF Energy | J18: SSW | K18: F | L18: TRUE | M18: TRUE
A19: BUP87361ic | B19: Lucy Darko | C19: 70 Parker Green, Palmerburgh, Dumfries and Galloway, CF8 6HR | D19: End of Terrace | E19: 2 | F19: Gas | G19: Fixed | H19: FALSE | I19: SSW | J19: SSW | K19: A | L19: TRUE | M19: FALSE
A20: VAI27858eo | B20: Rowan Burke | C20: Flat 4, 72 Cole Way, New Georgemouth, Greater London, ML1 2DT | D20: Flat | E20: 2 | F20: Electric | G20: Fixed | H20: FALSE | J20: SSW | K20: D | L20: TRUE | M20: FALSE
A21: GMM05130fq | B21: Naoimh Koch | C21: 68 Foster Avenue, Port Kellystad, Falkirk, HA82 3RS | D21: Mid Terrace | E21: 4 | F21: Gas | G21: Fixed | H21: FALSE | I21: Scottish Gas | J21: Scottish Gas | K21: A | L21: TRUE | M21: FALSE
A22: IMK68238zx | B22: Pierce O'Shiel | C22: 33 Davies Way, New Josephineberg, Cambridgeshire, M4W 6EL | D22: Semi Detached | E22: 5 | F22: Electric | G22: Fixed | H22: TRUE | J22: SSW | K22: B | L22: TRUE | M22: TRUE
A23: QQY75684zh | B23: Gina Morel | C23: 44 Roberts Avenue, North Brettville, Cambridgeshire, DH3 3XT | D23: Mid Terrace | E23: 2 | F23: Gas | G23: Fixed | H23: FALSE | I23: Scottish Gas | J23: Scottish Gas | K23: F | L23: FALSE | M23: FALSE
A24: DWS80052jt | B24: Gemma Swift-Sha | C24: 15 Morris Street, McDonaldborough, North Lanarkshire, DE17 4DF | D24: End of Terrace | E24: 3 | F24: Gas | G24: Fixed | H24: FALSE | I24: E. OFF. | J24: Scottish Gas | K24: A | L24: FALSE | M24: FALSE
A25: BMJ31234eq | B25: Rati Amoako-Batta | C25: 28 Duncan Green, Griffithshaven, Fermanagh, HP4N 5HS | D25: Detached | E25: 3 | F25: Electric | G25: Fixed | H25: FALSE | J25: Mpower | K25: E | L25: TRUE | M25: FALSE
A26: UDT27710qe | B26: Amalie Holst | C26: 44 Reid Green, Kellymouth, North Ayrshire, E5A 5GN | D26: Mid Terrace | E26: 4 | F26: Gas | G26: Variable | H26: FALSE | I26: SSW | J26: SSW | K26: E | L26: TRUE | M26: FALSE
A27: CJR13440zu | B27: Antoine Ravi | C27: 50 Kelly Way, Owenville, Essex, AB92 5US | D27: Semi Detached | E27: 2 | F27: Gas | G27: Variable | H27: FALSE | I27: Scottish Gas | J27: Scottish Gas | K27: C | L27: TRUE | M27: FALSE
A28: USJ25734gc | B28: Misha Agyapong-Ghosh | C28: 50 Farmer Green, New Alexburgh, Eilean Siar, E30 1NB | D28: Semi Detached | E28: 4 | F28: Gas | G28: Fixed | H28: FALSE | I28: Scottish Gas | J28: Scottish Gas | K28: B | L28: TRUE | M28: FALSE
A29: HPT27954kx | B29: Judith Jones-Vestergaard | C29: 33 Cook Way, Rileyshire, Armagh, W2T 0SS | D29: Detached | E29: 5 | F29: Electric | G29: Fixed | H29: TRUE | J29: Scottish Gas | K29: C | L29: TRUE | M29: FALSE
A30: RCA91956mi | B30: Kanav Goff | C30: 41 Ali Road, North Billy, Greater Manchester, WR8A 8AD | D30: Bungalow | E30: 3 | F30: Gas | G30: Fixed | H30: FALSE | I30: Mpower | J30: Mpower | K30: C | L30: TRUE | M30: FALSE
A31: UGG38599vg | B31: Mary Wood | C31: 50 Brown Road, Dianebury, Clackmannanshire, N34 8DN | D31: End of Terrace | E31: 2 | F31: Electric | G31: Fixed | H31: TRUE | J31: Scottish Gas | K31: B | L31: TRUE | M31: FALSE
A32: YBP06973su | B32: Marie Wali | C32: 47 Young Green, East Hollie, Tyrone, B6D 4HE | D32: Semi Detached | E32: 2 | F32: Gas | G32: Variable | H32: FALSE | I32: Scottish Gas | J32: Scottish Gas | K32: B | L32: TRUE | M32: FALSE
A33: VRT72609qa | B33: Lærke Kilmore | C33: 22 Turner Green, Nashbury, Perth and Kinross, ZE1E 5LS | D33: Detached | E33: 3 | F33: Gas | G33: Fixed | H33: FALSE | I33: Scottish Gas | J33: Scottish Gas | K33: C | L33: TRUE | M33: FALSE
A34: PBR62140zd | B34: Lynne Thomas | C34: 42 Robertson Way, Port Jenniferview, Essex, L64 2UJ | D34: Mid Terrace | E34: 2 | F34: Electric | G34: Variable | H34: FALSE | J34: Scottish Gas | K34: A | L34: TRUE | M34: FALSE
A35: TCO48434zf | B35: Diya Bryant-Neveu | C35: 22 Williams Street, Evanston, West Dunbartonshire, DN4E 7UD | D35: Detached | E35: 3 | F35: Gas | G35: Fixed | H35: FALSE | I35: Scottish Gas | J35: Scottish Gas | K35: C | L35: FALSE | M35: FALSE
A36: DRI02640jp | B36: Ronnie Beatty | C36: 71 Ellis Way, West Marian, Oxfordshire, PL0B 2ZW | D36: Semi Detached | E36: 2 | F36: Gas | G36: Fixed | H36: TRUE | I36: Scottish Gas | J36: Scottish Gas | K36: B | L36: TRUE | M36: FALSE
A37: BQY08319vl | B37: Katy Faull | C37: 75 Ali Green, Dobsonville, Stirling, HA3 0TT | D37: Semi Detached | E37: 3 | F37: Electric | G37: Fixed | H37: FALSE | J37: Scottish Gas | K37: D | L37: TRUE | M37: FALSE
A38: QFZ47094lj | B38: Robert McKevitt-Chevallier | C38: 71 Williams Way, Phillipsstad, West Dunbartonshire, ML3V 7GH | D38: Semi Detached | E38: 3 | F38: Gas | G38: Variable | H38: FALSE | I38: Mpower | J38: Scottish Gas | K38: E | L38: TRUE | M38: FALSE
A39: NUC71080hy | B39: Odeline Nyame | C39: 2 Chambers Street, Morleytown, Merionethshire, M2 9SD | D39: Mid Terrace | E39: 3 | F39: Electric | G39: Fixed | H39: FALSE | J39: Scottish Gas | K39: A | L39: TRUE | M39: FALSE
A40: PBW91252br | B40: Aayush Lauritsen | C40: 38 Higgins Road, Williamsport, Nottinghamshire, N2 9PX | D40: Detached | E40: 4 | F40: Gas | G40: Variable | H40: FALSE | I40: Scottish Gas | J40: Scottish Gas | K40: C | L40: TRUE | M40: TRUE
...

Sheet 2020
A1: Customer ID | B1: Reading Day | C1: Reading Month | D1: Reading Year | E1: Gas Reading (Price) | F1: Electric Reading (Price) | H1: solar panels
A2: OXQ92940zy | B2: 17 | C2: 12 | D2: 2020 | E2: None | F2: 244.9 | H2: =_xlfn.XLOOKUP('Data Source 1_customer readings'!A2,'Data Source 1_customer readings'!A2:A2400,'Data Source 1_customer readings'!J2:J2400) -> 0
A3: LQK10370cq | B3: 20 | C3: 12 | D3: 2020 | E3: None | F3: 206.46 | H3: =_xlfn.XLOOKUP('Data Source 1_customer readings'!A3,'Data Source 1_customer readings'!A3:A2401,'Data Source 1_customer readings'!J3:J2401) -> 0
A4: BAK65354tq | B4: 5 | C4: 11 | D4: 2020 | E4: None | F4: 206.1 | H4: =_xlfn.XLOOKUP('Data Source 1_customer readings'!A4,'Data Source 1_customer readings'!A4:A2402,'Data Source 1_customer readings'!J4:J2402) -> 0
A5: RQP11655zi | B5: 22 | C5: 2 | D5: 2020 | E5: None | F5: 204.12 | H5: =_xlfn.XLOOKUP('Data Source 1_customer readings'!A5,'Data Source 1_customer readings'!A5:A2403,'Data Source 1_customer readings'!J5:J2403) -> FALSE
A6: QJY78975xx | B6: 1 | C6: 12 | D6: 2020 | E6: None | F6: 203.05 | H6: =_xlfn.XLOOKUP('Data Source 1_customer readings'!A6,'Data Source 1_customer readings'!A6:A2404,'Data Source 1_customer readings'!J6:J2404) -> 0
A7: LQK10370cq | B7: 20 | C7: 1 | D7: 2020 | E7: None | F7: 202.43 | H7: =_xlfn.XLOOKUP('Data Source 1_customer readings'!A7,'Data Source 1_customer readings'!A7:A2405,'Data Source 1_customer readings'!J7:J2405) -> 0
A8: SDI07287zg | B8: 22 | C8: 1 | D8: 2020 | E8: None | F8: 199.33 | H8: =_xlfn.XLOOKUP('Data Source 1_customer readings'!A8,'Data Source 1_customer readings'!A8:A2406,'Data Source 1_customer readings'!J8:J2406) -> 0
A9: AOY53449sm | B9: 1 | C9: 1 | D9: 2020 | E9: None | F9: 198.09 | H9: =_xlfn.XLOOKUP('Data Source 1_customer readings'!A9,'Data Source 1_customer readings'!A9:A2407,'Data Source 1_customer readings'!J9:J2407) -> 0
A10: AOY53449sm | B10: 1 | C10: 12 | D10: 2020 | E10: None | F10: 194.06 | H10: =_xlfn.XLOOKUP('Data Source 1_customer readings'!A10,'Data Source 1_customer readings'!A10:A2408,'Data Source 1_customer readings'!J10:J2408) -> 0
A11: SDI07287zg | B11: 22 | C11: 12 | D11: 2020 | E11: None | F11: 193.13 | H11: =_xlfn.XLOOKUP('Data Source 1_customer readings'!A11,'Data Source 1_customer readings'!A11:A2409,'Data Source 1_customer readings'!J11:J2409) -> 0
A12: QJY78975xx | B12: 1 | C12: 1 | D12: 2020 | E12: None | F12: 192.2 | H12: =_xlfn.XLOOKUP('Data Source 1_customer readings'!A12,'Data Source 1_customer readings'!A12:A2410,'Data Source 1_customer readings'!J12:J2410) -> 0
A13: ABS01137oq | B13: 5 | C13: 11 | D13: 2020 | E13: None | F13: 187.8 | H13: =_xlfn.XLOOKUP('Data Source 1_customer readings'!A13,'Data Source 1_customer readings'!A13:A2411,'Data Source 1_customer readings'!J13:J2411) -> 0
... A144: MMT85033aa | B144: 24 | C144: 9 | D144: 2020 | E144: None | F144: 53.7 | H144: =_xlfn.XLOOKUP('Data Source 1_customer readings'!A144,'Data Source 1_customer readings'!A144:A2542,'Data Source 1_customer readings'!J144:J2542) -> 0
A145: LVY78103rt | B145: 3 | C145: 1 | D145: 2020 | E145: 177.01 | F145: 87.73 | H145: =_xlfn.XLOOKUP('Data Source 1_customer readings'!A145,'Data Source 1_customer readings'!A145:A2543,'Data Source 1_customer readings'!J145:J2543) -> 0
A146: LVY78103rt | B146: 3 | C146: 12 | D146: 2020 | E146: 177.01 | F146: 77.5 | H146: =_xlfn.XLOOKUP('Data Source 1_customer readings'!A146,'Data Source 1_customer readings'!A146:A2544,'Data Source 1_customer readings'!J146:J2544) -> 0
A147: UPF42692ng | B147: 7 | C147: 11 | D147: 2020 | E147: 162.9 | F147: 79.2 | H147: =_xlfn.XLOOKUP('Data Source 1_customer readings'!A147,'Data Source 1_customer readings'!A147:A2545,'Data Source 1_customer readings'!J147:J2545) -> 0
A148: UPF42692ng | B148: 7 | C148: 12 | D148: 2020 | E148: 160.58 | F148: 84.01 | H148: =_xlfn.XLOOKUP('Data Source 1_customer readings'!A148,'Data Source 1_customer readings'!A148:A2546,'Data Source 1_customer readings'!J148:J2546) -> FALSE
A149: UAM51525zs | B149: 2 | C149: 1 | D149: 2020 | E149: 153.14 | F149: 66.96 | H149: =_xlfn.XLOOKUP('Data Source 1_customer readings'!A149,'Data Source 1_customer readings'!A149:A2547,'Data Source 1_customer readings'!J149:J2547) -> 0
A150: YWP66519xo | B150: 23 | C150: 12 | D150: 2020 | E150: 149.73 | F150: 105.4 | H150: =_xlfn.XLOOKUP('Data Source 1_customer readings'!A150,'Data Source 1_customer readings'!A150:A2548,'Data Source 1_customer readings'!J150:J2548) -> 0
A151: LVY78103rt | B151: 3 | C151: 2 | D151: 2020 | E151: 148.96 | F151: 82.04 | H151: =_xlfn.XLOOKUP('Data Source 1_customer readings'!A151,'Data Source 1_customer readings'!A151:A2549,'Data Source 1_customer readings'!J151:J2549) -> 0
A152: YWP66519xo | B152: 23 | C152: 11 | D152: 2020 | E152: 148.5 | F152: 93 | H152: =_xlfn.XLOOKUP('Data Source 1_customer readings'!A152,'Data Source 1_customer readings'!A152:A2550,'Data Source 1_customer readings'!J152:J2550) -> TRUE
A153: DAS61546hl | B153: 20 | C153: 11 | D153: 2020 | E153: 147.6 | F153: 76.8 | H153: =_xlfn.XLOOKUP('Data Source 1_customer readings'!A153,'Data Source 1_customer readings'!A153:A2551,'Data Source 1_customer readings'!J153:J2551) -> 0
A154: KXJ20268ur | B154: 5 | C154: 11 | D154: 2020 | E154: 147.6 | F154: 57.6 | H154: =_xlfn.XLOOKUP('Data Source 1_customer readings'!A154,'Data Source 1_customer readings'!A154:A2552,'Data Source 1_customer readings'!J154:J2552) -> 0
A155: UPF42692ng | B155: 7 | C155: 1 | D155: 2020 | E155: 145.39 | F155: 97.03 | H155: =_xlfn.XLOOKUP('Data Source 1_customer readings'!A155,'Data Source 1_customer readings'!A155:A2553,'Data Source 1_customer readings'!J155:J2553) -> 0
A156: XRJ71787yc | B156: 8 | C156: 12 | D156: 2020 | E156: 144.15 | F156: 70.06 | H156: =_xlfn.XLOOKUP('Data Source 1_customer readings'!A156,'Data Source 1_customer readings'!A156:A2554,'Data Source 1_customer readings'!J156:J2554) -> 0
... A1200: GZR74544gy | B1200: 18 | C1200: 6 | D1200: 2020 | E1200: 0 | F1200: 86.1 | H1200: =_xlfn.XLOOKUP('Data Source 1_customer readings'!A1200,'Data Source 1_customer readings'!A1200:A3598,'Data Source 1_customer readings'!J1200:J3598) -> 0
A1201: OVP60227cf | B1201: 25 | C1201: 3 | D1201: 2020 | F1201: 69.44 | H1201: =_xlfn.XLOOKUP('Data Source 1_customer readings'!A1201,'Data Source 1_customer readings'!A1201:A3599,'Data Source 1_customer readings'!J1201:J3599) -> 0
E1203: =SUM(E145:E1202) -> 53627.34 | F1203: =SUM(F2:F1202) -> 125845.03
A1206: =COUNTA(_xlfn.UNIQUE(A2:A1201)) -> 100

Sheet double check
A1: Customer ID | B1: Reading Day | C1: Reading Month | D1: Reading Year | E1: Gas Reading (Price) | F1: Electric Reading (Price)
A2: OXQ92940zy | B2: 17 | C2: 12 | D2: 2020 | E2: None | F2: 244.9
A3: YOB39332fb | B3: 14 | C3: 11 | D3: 2020 | E3: 0 | F3: 234.3
A4: OXQ92940zy | B4: 17 | C4: 2 | D4: 2020 | E4: 0 | F4: 223.72
A5: OXQ92940zy | B5: 17 | C5: 1 | D5: 2020 | E5: 0 | F5: 220.72
A6: CKQ72473xh | B6: 8 | C6: 1 | D6: 2020 | E6: 0 | F6: 219.48
A7: SDI07287zg | B7: 22 | C7: 11 | D7: 2020 | E7: 0 | F7: 217.5
A8: OXQ92940zy | B8: 17 | C8: 11 | D8: 2020 | E8: 0 | F8: 213.9
A9: RQP11655zi | B9: 22 | C9: 12 | D9: 2020 | E9: 0 | F9: 209.87
A10: OFD38290ot | B10: 2 | C10: 1 | D10: 2020 | E10: 0 | F10: 209.25
A11: RQP11655zi | B11: 22 | C11: 1 | D11: 2020 | E11: 0 | F11: 209.25
A12: LQK10370cq | B12: 20 | C12: 12 | D12: 2020 | E12: None | F12: 206.46
A13: LQK10370cq | B13: 20 | C13: 11 | D13: 2020 | E13: 0 | F13: 206.4
A14: BAK65354tq | B14: 5 | C14: 11 | D14: 2020 | E14: None | F14: 206.1
A15: BAK65354tq | B15: 5 | C15: 1 | D15: 2020 | E15: 0 | F15: 205.84
A16: OFD38290ot | B16: 2 | C16: 11 | D16: 2020 | E16: 0 | F16: 205.5
A17: YFB97062xj | B17: 5 | C17: 1 | D17: 2020 | E17: 0 | F17: 205.22
A18: PCY81777xu | B18: 15 | C18: 1 | D18: 2020 | E18: 0 | F18: 204.6
A19: RQP11655zi | B19: 22 | C19: 2 | D19: 2020 | E19: None | F19: 204.12
A20: OFD38290ot | B20: 2 | C20: 12 | D20: 2020 | E20: 0 | F20: 203.98
A21: YFB97062xj | B21: 5 | C21: 12 | D21: 2020 | E21: 0 | F21: 203.98
A22: CKQ72473xh | B22: 8 | C22: 11 | D22: 2020 | E22: 0 | F22: 203.7
A23: YOB39332fb | B23: 14 | C23: 1 | D23: 2020 | E23: 0 | F23: 203.67
A24: QJY78975xx | B24: 1 | C24: 12 | D24: 2020 | E24: None | F24: 203.05
A25: OXQ92940zy | B25: 17 | C25: 10 | D25: 2020 | E25: 0 | F25: 202.74
A26: LQK10370cq | B26: 20 | C26: 1 | D26: 2020 | E26: None | F26: 202.43
A27: CKQ72473xh | B27: 8 | C27: 12 | D27: 2020 | E27: 0 | F27: 201.19
A28: YOB39332fb | B28: 14 | C28: 2 | D28: 2020 | E28: 0 | F28: 199.92
A29: SDI07287zg | B29: 22 | C29: 1 | D29: 2020 | E29: None | F29: 199.33
A30: PBR62140zd | B30: 14 | C30: 1 | D30: 2020 | E30: 0 | F30: 198.71
A31: HPT27954kx | B31: 22 | C31: 1 | D31: 2020 | E31: 0 | F31: 198.71
A32: AOY53449sm | B32: 1 | C32: 1 | D32: 2020 | E32: None | F32: 198.09
A33: VJT76037py | B33: 5 | C33: 1 | D33: 2020 | E33: 0 | F33: 197.78
A34: BAK65354tq | B34: 5 | C34: 2 | D34: 2020 | E34: 0 | F34: 196.84
A35: PCY81777xu | B35: 15 | C35: 11 | D35: 2020 | E35: 0 | F35: 196.8
A36: HPT27954kx | B36: 22 | C36: 11 | D36: 2020 | E36: 0 | F36: 195.3
A37: YOB39332fb | B37: 14 | C37: 12 | D37: 2020 | E37: 0 | F37: 194.99
A38: PCY81777xu | B38: 15 | C38: 12 | D38: 2020 | E38: 0 | F38: 194.68
A39: AOY53449sm | B39: 1 | C39: 12 | D39: 2020 | E39: None | F39: 194.06
A40: SDI07287zg | B40: 22 | C40: 12 | D40: 2020 | E40: None | F40: 193.13
...

Sheet Sheet2
A1: Customer ID | B1: Reading Day | C1: Reading Month | D1: Reading Year | E1: Gas Reading (Price) | F1: Electric Reading (Price)
A2: OXQ92940zy | B2: 17 | C2: 12 | D2: 2021 | E2: None | F2: 272.49
A3: OXQ92940zy | B3: 17 | C3: 1 | D3: 2021 | E3: 0 | F3: 256.37
A4: OFD38290ot | B4: 2 | C4: 1 | D4: 2021 | E4: 0 | F4: 246.45
A5: OFD38290ot | B5: 2 | C5: 12 | D5: 2021 | E5: 0 | F5: 243.35
A6: OXQ92940zy | B6: 17 | C6: 11 | D6: 2021 | E6: 0 | F6: 237.9
A7: YOB39332fb | B7: 14 | C7: 1 | D7: 2021 | E7: 0 | F7: 233.74
A8: SDI07287zg | B8: 22 | C8: 11 | D8: 2021 | E8: 0 | F8: 231.9
A9: OFD38290ot | B9: 2 | C9: 11 | D9: 2021 | E9: None | F9: 226.8
A10: BAK65354tq | B10: 5 | C10: 11 | D10: 2021 | E10: 0 | F10: 224.1
A11: BAK65354tq | B11: 5 | C11: 12 | D11: 2021 | E11: None | F11: 222.89
A12: QJY78975xx | B12: 1 | C12: 1 | D12: 2021 | E12: 0 | F12: 222.89
A13: YFB97062xj | B13: 5 | C13: 12 | D13: 2021 | E13: 0 | F13: 221.03
A14: BAK65354tq | B14: 5 | C14: 1 | D14: 2021 | E14: 0 | F14: 219.17
A15: PBR62140zd | B15: 14 | C15: 1 | D15: 2021 | E15: 0 | F15: 218.86
A16: PCY81777xu | B16: 15 | C16: 11 | D16: 2021 | E16: 0 | F16: 216.9
A17: OXQ92940zy | B17: 17 | C17: 2 | D17: 2021 | E17: 0 | F17: 214.48
A18: VJT76037py | B18: 5 | C18: 11 | D18: 2021 | E18: 0 | F18: 213.9
A19: QJY78975xx | B19: 1 | C19: 12 | D19: 2021 | E19: None | F19: 211.73
A20: JGD49544db | B20: 2 | C20: 1 | D20: 2021 | E20: 0 | F20: 208.01
A21: BQY08319vl | B21: 12 | C21: 12 | D21: 2021 | E21: 0 | F21: 206.77
A22: QJY78975xx | B22: 1 | C22: 11 | D22: 2021 | E22: 0 | F22: 206.1
A23: GOC42881px | B23: 5 | C23: 12 | D23: 2021 | E23: 0 | F23: 205.53
A24: RQP11655zi | B24: 22 | C24: 1 | D24: 2021 | E24: 0 | F24: 205.22
A25: BQY08319vl | B25: 12 | C25: 1 | D25: 2021 | E25: 0 | F25: 203.05
A26: YOB39332fb | B26: 14 | C26: 11 | D26: 2021 | E26: 0 | F26: 202.5
A27: YFB97062xj | B27: 5 | C27: 1 | D27: 2021 | E27: None | F27: 201.5
A28: ZOA34374mt | B28: 15 | C28: 12 | D28: 2021 | E28: 0 | F28: 200.26
A29: SDI07287zg | B29: 22 | C29: 1 | D29: 2021 | E29: 0 | F29: 199.95
A30: YOB39332fb | B30: 14 | C30: 2 | D30: 2021 | E30: None | F30: 199.92
A31: YOB39332fb | B31: 14 | C31: 12 | D31: 2021 | E31: 0 | F31: 199.33
A32: OFD38290ot | B32: 2 | C32: 2 | D32: 2021 | E32: 0 | F32: 198.8
A33: GOC42881px | B33: 5 | C33: 1 | D33: 2021 | E33: 0 | F33: 198.71
A34: OXQ92940zy | B34: 17 | C34: 10 | D34: 2021 | E34: 0 | F34: 198.71
A35: PCY81777xu | B35: 15 | C35: 1 | D35: 2021 | E35: None | F35: 198.4
A36: PCY81777xu | B36: 15 | C36: 12 | D36: 2021 | E36: 0 | F36: 197.78
A37: NUC71080hy | B37: 21 | C37: 12 | D37: 2021 | E37: None | F37: 197.47
A38: YFB97062xj | B38: 5 | C38: 11 | D38: 2021 | E38: 0 | F38: 197.1
A39: ABS01137oq | B39: 5 | C39: 12 | D39: 2021 | E39: 0 | F39: 196.85
A40: OXQ92940zy | B40: 17 | C40: 3 | D40: 2021 | E40: 0 | F40: 196.54
...

Sheet Sheet4
A1: Customer ID | B1: Reading Day | C1: Reading Month | D1: Reading Year | E1: Gas Reading (Price) | F1: Electric Reading (Price) | H1: solar panels
A2: OXQ92940zy | B2: 17 | C2: 12 | D2: 2021 | E2: None | F2: 272.49 | H2: =_xlfn.XLOOKUP('Data Source 1_customer readings'!A2,'Data Source 1_customer readings'!A2:A2400,'Data Source 1_customer readings'!J2:J2400) -> 0
A3: OFD38290ot | B3: 2 | C3: 11 | D3: 2021 | E3: None | F3: 226.8 | H3: =_xlfn.XLOOKUP('Data Source 1_customer readings'!A3,'Data Source 1_customer readings'!A3:A2401,'Data Source 1_customer readings'!J3:J2401) -> 0
A4: BAK65354tq | B4: 5 | C4: 12 | D4: 2021 | E4: None | F4: 222.89 | H4: =_xlfn.XLOOKUP('Data Source 1_customer readings'!A4,'Data Source 1_customer readings'!A4:A2402,'Data Source 1_customer readings'!J4:J2402) -> 0
A5: QJY78975xx | B5: 1 | C5: 12 | D5: 2021 | E5: None | F5: 211.73 | H5: =_xlfn.XLOOKUP('Data Source 1_customer readings'!A5,'Data Source 1_customer readings'!A5:A2403,'Data Source 1_customer readings'!J5:J2403) -> FALSE
A6: YFB97062xj | B6: 5 | C6: 1 | D6: 2021 | E6: None | F6: 201.5 | H6: =_xlfn.XLOOKUP('Data Source 1_customer readings'!A6,'Data Source 1_customer readings'!A6:A2404,'Data Source 1_customer readings'!J6:J2404) -> 0
A7: YOB39332fb | B7: 14 | C7: 2 | D7: 2021 | E7: None | F7: 199.92 | H7: =_xlfn.XLOOKUP('Data Source 1_customer readings'!A7,'Data Source 1_customer readings'!A7:A2405,'Data Source 1_customer readings'!J7:J2405) -> 0
A8: PCY81777xu | B8: 15 | C8: 1 | D8: 2021 | E8: None | F8: 198.4 | H8: =_xlfn.XLOOKUP('Data Source 1_customer readings'!A8,'Data Source 1_customer readings'!A8:A2406,'Data Source 1_customer readings'!J8:J2406) -> 0
A9: NUC71080hy | B9: 21 | C9: 12 | D9: 2021 | E9: None | F9: 197.47 | H9: =_xlfn.XLOOKUP('Data Source 1_customer readings'!A9,'Data Source 1_customer readings'!A9:A2407,'Data Source 1_customer readings'!J9:J2407) -> 0
A10: WBO33198ot | B10: 8 | C10: 1+C18:C32 | D10: 2021 | E10: None | F10: 195.92 | H10: =_xlfn.XLOOKUP('Data Source 1_customer readings'!A10,'Data Source 1_customer readings'!A10:A2408,'Data Source 1_customer readings'!J10:J2408) -> 0
A11: WLA72030fi | B11: 7 | C11: 12 | D11: 2021 | E11: None | F11: 193.75 | H11: =_xlfn.XLOOKUP('Data Source 1_customer readings'!A11,'Data Source 1_customer readings'!A11:A2409,'Data Source 1_customer readings'!J11:J2409) -> 0
A12: BQY08319vl | B12: 12 | C12: 11 | D12: 2021 | E12: None | F12: 192.9 | H12: =_xlfn.XLOOKUP('Data Source 1_customer readings'!A12,'Data Source 1_customer readings'!A12:A2410,'Data Source 1_customer readings'!J12:J2410) -> 0
A13: RQP11655zi | B13: 22 | C13: 12 | D13: 2021 | E13: None | F13: 192.82 | H13: =_xlfn.XLOOKUP('Data Source 1_customer readings'!A13,'Data Source 1_customer readings'!A13:A2411,'Data Source 1_customer readings'!J13:J2411) -> 0
A14: RQP11655zi | B14: 22 | C14: 11 | D14: 2021 | E14: None | F14: 186.9 | H14: =_xlfn.XLOOKUP('Data Source 1_customer readings'!A14,'Data Source 1_customer readings'!A14:A2412,'Data Source 1_customer readings'!J14:J2412) -> 0
A15: XHW94189wg | B15: 24 | C15: 11 | D15: 2021 | E15: None | F15: 186.6 | H15: =_xlfn.XLOOKUP('Data Source 1_customer readings'!A15,'Data Source 1_customer readings'!A15:A2413,'Data Source 1_customer readings'!J15:J2413) -> 0
A16: NUC71080hy | B16: 21 | C16: 2 | D16: 2021 | E16: None | F16: 186.2 | H16: =_xlfn.XLOOKUP('Data Source 1_customer readings'!A16,'Data Source 1_customer readings'!A16:A2414,'Data Source 1_customer readings'!J16:J2414) -> 0
A17: VJT76037py | B17: 5 | C17: 1 | D17: 2021 | E17: None | F17: 182.9 | H17: =_xlfn.XLOOKUP('Data Source 1_customer readings'!A17,'Data Source 1_customer readings'!A17:A2415,'Data Source 1_customer readings'!J17:J2415) -> 0
A18: IMK68238zx | B18: 10 | C18: 1 | D18: 2021 | E18: None | F18: 180.73 | H18: =_xlfn.XLOOKUP('Data Source 1_customer readings'!A18,'Data Source 1_customer readings'!A18:A2416,'Data Source 1_customer readings'!J18:J2416) -> 0
A19: NUC71080hy | B19: 21 | C19: 11 | D19: 2021 | E19: None | F19: 180.3 | H19: =_xlfn.XLOOKUP('Data Source 1_customer readings'!A19,'Data Source 1_customer readings'!A19:A2417,'Data Source 1_customer readings'!J19:J2417) -> 0
A20: PBR62140zd | B20: 14 | C20: 12 | D20: 2021 | E20: None | F20: 177.32 | H20: =_xlfn.XLOOKUP('Data Source 1_customer readings'!A20,'Data Source 1_customer readings'!A20:A2418,'Data Source 1_customer readings'!J20:J2418) -> 0
A21: NUC71080hy | B21: 21 | C21: 1 | D21: 2021 | E21: None | F21: 176.39 | H21: =_xlfn.XLOOKUP('Data Source 1_customer readings'!A21,'Data Source 1_customer readings'!A21:A2419,'Data Source 1_customer readings'!J21:J2419) -> 0
A22: ABS01137oq | B22: 5 | C22: 1 | D22: 2021 | E22: None | F22: 176.08 | H22: =_xlfn.XLOOKUP('Data Source 1_customer readings'!A22,'Data Source 1_customer readings'!A22:A2420,'Data Source 1_customer readings'!J22:J2420) -> 0
... A138: OVP60227cf | B138: 25 | C138: 2 | D138: 2021 | E138: None | F138: 54.6 | H138: =_xlfn.XLOOKUP('Data Source 1_customer readings'!A138,'Data Source 1_customer readings'!A138:A2536,'Data Source 1_customer readings'!J138:J2536) -> 0
A139: UOT01483nx | B139: 18 | C139: 1 | D139: 2021 | E139: 162.44 | F139: 105.09 | H139: =_xlfn.XLOOKUP('Data Source 1_customer readings'!A139,'Data Source 1_customer readings'!A139:A2537,'Data Source 1_customer readings'!J139:J2537) -> 0
A140: UPF42692ng | B140: 7 | C140: 1 | D140: 2021 | E140: 160.89 | F140: 78.12 | H140: =_xlfn.XLOOKUP('Data Source 1_customer readings'!A140,'Data Source 1_customer readings'!A140:A2538,'Data Source 1_customer readings'!J140:J2538) -> 0
A141: LVY78103rt | B141: 3 | C141: 1 | D141: 2021 | E141: 160.58 | F141: 90.21 | H141: =_xlfn.XLOOKUP('Data Source 1_customer readings'!A141,'Data Source 1_customer readings'!A141:A2539,'Data Source 1_customer readings'!J141:J2539) -> 0
A142: YWP66519xo | B142: 23 | C142: 12 | D142: 2021 | E142: 159.96 | F142: 101.99 | H142: =_xlfn.XLOOKUP('Data Source 1_customer readings'!A142,'Data Source 1_customer readings'!A142:A2540,'Data Source 1_customer readings'!J142:J2540) -> 0
A143: UDT27710qe | B143: 25 | C143: 12 | D143: 2021 | E143: 158.1 | F143: 115.63 | H143: =_xlfn.XLOOKUP('Data Source 1_customer readings'!A143,'Data Source 1_customer readings'!A143:A2541,'Data Source 1_customer readings'!J143:J2541) -> 0
A144: UDT27710qe | B144: 25 | C144: 1 | D144: 2021 | E144: 157.17 | F144: 98.89 | H144: =_xlfn.XLOOKUP('Data Source 1_customer readings'!A144,'Data Source 1_customer readings'!A144:A2542,'Data Source 1_customer readings'!J144:J2542) -> 0
A145: KDF35765ns | B145: 21 | C145: 12 | D145: 2021 | E145: 155.31 | F145: 122.45 | H145: =_xlfn.XLOOKUP('Data Source 1_customer readings'!A145,'Data Source 1_customer readings'!A145:A2543,'Data Source 1_customer readings'!J145:J2543) -> 0
A146: RXY68626yj | B146: 16 | C146: 11 | D146: 2021 | E146: 154.8 | F146: 111 | H146: =_xlfn.XLOOKUP('Data Source 1_customer readings'!A146,'Data Source 1_customer readings'!A146:A2544,'Data Source 1_customer readings'!J146:J2544) -> 0
A147: KXJ20268ur | B147: 5 | C147: 12 | D147: 2021 | E147: 154.07 | F147: 81.53 | H147: =_xlfn.XLOOKUP('Data Source 1_customer readings'!A147,'Data Source 1_customer readings'!A147:A2545,'Data Source 1_customer readings'!J147:J2545) -> 0
A148: CGL78428bi | B148: 22 | C148: 11 | D148: 2021 | E148: 152.1 | F148: 104.7 | H148: =_xlfn.XLOOKUP('Data Source 1_customer readings'!A148,'Data Source 1_customer readings'!A148:A2546,'Data Source 1_customer readings'!J148:J2546) -> FALSE
A149: CGL78428bi | B149: 22 | C149: 1 | D149: 2021 | E149: 151.59 | F149: 114.7 | H149: =_xlfn.XLOOKUP('Data Source 1_customer readings'!A149,'Data Source 1_customer readings'!A149:A2547,'Data Source 1_customer readings'!J149:J2547) -> 0
A150: TCO48434zf | B150: 1 | C150: 1 | D150: 2021 | E150: 150.97 | F150: 86.8 | H150: =_xlfn.XLOOKUP('Data Source 1_customer readings'!A150,'Data Source 1_customer readings'!A150:A2548,'Data Source 1_customer readings'!J150:J2548) -> 0
... A1201: WNJ39833gm | B1201: 21 | C1201: 6 | D1201: 2021 | E1201: 0 | F1201: 85.2 | H1201: =_xlfn.XLOOKUP('Data Source 1_customer readings'!A1201,'Data Source 1_customer readings'!A1201:A3599,'Data Source 1_customer readings'!J1201:J3599) -> 0
E1203: =SUM(E139:E1202) -> 56839.77 | F1203: =SUM(F2:F1202) -> 130566.16
A1207: =COUNTA(_xlfn.UNIQUE(A2:A1201)) -> 100
